
<mujoco>
	<include file="./common/cueball_shared.xml"/>

	<worldbody>
		<include file="./common/cueball_table.xml"/>
		<body name="ball_0" pos="0 0 .035">
		  <joint name="ball_0_root_x" type="slide"  pos="0 0 0" axis="1 0 0"/>
		  <joint name="ball_0_root_y" type="slide"  pos="0 0 0" axis="0 1 0"/>
		  <geom name="ball_0" type="sphere" size=".0305" mass=".1" pos="-0.35 0.0315 0" rgba="0.9 0.1 0.1 1.0" solref="-500 -10"/>
		</body>
		<body name="ball_1" pos="0 0 .035">
		  <joint name="ball_1_root_x" type="slide"  pos="0 0 0" axis="1 0 0"/>
		  <joint name="ball_1_root_y" type="slide"  pos="0 0 0" axis="0 1 0"/>
		  <geom name="ball_1" type="sphere" size=".0305" mass=".1" pos="-0.35 -0.0315 0" rgba="0.1 0.9 0.1 1.0" solref="-500 -10"/>
		</body>
		<body name="ball_2" pos="0 0 .035">
		  <joint name="ball_2_root_x" type="slide"  pos="0 0 0" axis="1 0 0"/>
		  <joint name="ball_2_root_y" type="slide"  pos="0 0 0" axis="0 1 0"/>
		  <geom name="ball_2" type="sphere" size=".0305" mass=".1" pos="-0.295 0.0 0" rgba="0.1 0.1 0.9 1.0" solref="-500 -10"/>
		</body>
	</worldbody>
</mujoco>